[2025-09-30T17:02:55.316+0000] {scheduler_job_runner.py:769} ERROR - Executor reports task instance <TaskInstance: dag1.test_hello scheduled__2025-09-30T00:09:00+00:00 [queued]> finished (failed) although the task says it's queued. (Info: None) Was the task killed externally?
